<?xml version="1.0" encoding="UTF-8" ?>
<testsuite name="tst_VerifyExceptionThrown" timestamp="@TEST_START_TIME@" hostname="@HOSTNAME@" tests="13" failures="7" errors="0" skipped="0" time="@TEST_DURATION@">
  <properties>
    <property name="QTestVersion" value="@INSERT_QT_VERSION_HERE@"/>
    <property name="QtVersion" value="@INSERT_QT_VERSION_HERE@"/>
    <property name="QtBuild" value=""/>
  </properties>
  <testcase name="initTestCase" classname="tst_VerifyExceptionThrown" time="@TEST_DURATION@"/>
  <testcase name="testCorrectStdTypes" classname="tst_VerifyExceptionThrown" time="@TEST_DURATION@"/>
  <testcase name="testCorrectStdExceptions" classname="tst_VerifyExceptionThrown" time="@TEST_DURATION@"/>
  <testcase name="testCorrectMyExceptions" classname="tst_VerifyExceptionThrown" time="@TEST_DURATION@"/>
  <testcase name="testCorrectNoException" classname="tst_VerifyExceptionThrown" time="@TEST_DURATION@"/>
  <testcase name="testFailInt" classname="tst_VerifyExceptionThrown" time="@TEST_DURATION@">
    <failure type="fail" message="Expected an exception of type double to be thrown, but caught unknown exception"/>
  </testcase>
  <testcase name="testFailStdString" classname="tst_VerifyExceptionThrown" time="@TEST_DURATION@">
    <failure type="fail" message="Expected an exception of type char* to be thrown, but caught unknown exception"/>
  </testcase>
  <testcase name="testFailStdRuntimeError" classname="tst_VerifyExceptionThrown" time="@TEST_DURATION@">
    <failure type="fail" message="Expected an exception of type std::runtime_error to be thrown, but caught std::exception with message logic error"/>
  </testcase>
  <testcase name="testFailMyException" classname="tst_VerifyExceptionThrown" time="@TEST_DURATION@">
    <failure type="fail" message="Expected an exception of type MyBaseException to be thrown, but caught std::exception with message logic error"/>
  </testcase>
  <testcase name="testFailMyDerivedException" classname="tst_VerifyExceptionThrown" time="@TEST_DURATION@">
    <failure type="fail" message="Expected an exception of type std::runtime_error to be thrown, but caught std::exception with message MyDerivedException"/>
  </testcase>
  <testcase name="testFailNoException" classname="tst_VerifyExceptionThrown" time="@TEST_DURATION@">
    <failure type="fail" message="Expected exception of type std::exception to be thrown but no exception caught"/>
  </testcase>
  <testcase name="testFailNoException2" classname="tst_VerifyExceptionThrown" time="@TEST_DURATION@">
    <failure type="fail" message="Expected no exception to be thrown, but caught std::exception with message This line doesn&apos;t throw"/>
  </testcase>
  <testcase name="cleanupTestCase" classname="tst_VerifyExceptionThrown" time="@TEST_DURATION@"/>
</testsuite>
